Workbook

Sheet 퇴직예정자(65_80년생)
A1: EMPNO | B1: EMPNMK | C1: 생년월일 | D1: RESCOD | E1: STRTDT | F1: EMPDIV | G1: PAYDIV | H1: JOBGRPH | I1: JOBGRPM | J1: JOBGRPL | K1: PAYGRD | L1: JOBKND | M1: 직군 | N1: 직군 | O1: DEPTCD | P1: 부서 | Q1: 부서 | R1: JOBDTY | S1: JOBKIND | T1: PAYSEQ | U1: FSAMDT | V1: ENDDT | W1: USESTS | X1: CNGREYN | Y1: COSTDIV | Z1: DPOFFDT | AA1: DTYPRT | AB1: CLSWRKCD | AC1: CLSCD | AD1: LAMDT | AE1: LRMDT | AF1: WRDT | AG1: WRID | AH1: UPDT | AI1: UPID | AJ1: COMDT | AK1: COMID | AL1: WRKIND | AM1: FIRDT | AN1: CONDIV | AO1: JIKPRT
A2: IT200309 | B2: 임재현 | C2: 650701 | D2: E75FAD0DE4571B96EE914468CF24605D | E2: 19990524 | F2: 2 | G2: 2 | H2: 12 | I2: 18 | J2: 19 | K2: 2A | L2: 01 | M2: 관리 | N2: =VLOOKUP(L2,직군코드!$A$2:$B$12,2,FALSE) -> 관리 | O2: 003C0100 | P2: 인재양성팀 | Q2: =VLOOKUP(O2,부서코드!$B$9:$C$244,2,FALSE) -> 인재양성팀 | R2: 50 | S2: 1 | T2: 30 | U2: 20210601 | W2: 0 | X2: 1 | Y2: A100 | Z2: 20250101 | AD2: 20190701 | AE2: 20200601 | AH2: 20250101060000 | AI2: SYSTEM | AJ2: 20180724 | AK2: IT201052 | AL2: 0000 | AM2: 19990524 | AO2: 05
A3: IT201267 | B3: 강경식 | C3: 650710 | D3: 72337BB847784A371CC9DE8F1BC90AC4 | E3: 19971021 | F3: 9 | G3: 1 | H3: 12 | I3: 18 | J3: 19 | K3: 4A | L3: 03 | M3: 사무 | N3: =VLOOKUP(L3,직군코드!$A$2:$B$12,2,FALSE) -> 사무 | O3: 003C0100 | P3: 인재양성팀 | Q3: =VLOOKUP(O3,부서코드!$B$9:$C$244,2,FALSE) -> 인재양성팀 | R3: 50 | S3: 1 | T3: 29 | U3: 20260801 | W3: 0 | X3: 1 | Y3: A100 | Z3: 20250101 | AD3: 20220321 | AE3: 20250801 | AF3: 20111224 | AG3: IT201159 | AH3: 20250801060000 | AI3: SYSTEM | AJ3: 20120516 | AK3: IT201159 | AL3: 0000 | AM3: 19971021 | AO3: 03
A4: IT200199 | B4: 김양정 | C4: 650714 | D4: D87CAC87CFBDD0086E88A53ED0C6DF8C | E4: 19990524 | F4: 2 | G4: 2 | H4: 12 | I4: 18 | J4: 19 | K4: 1A | L4: 01 | M4: 관리 | N4: =VLOOKUP(L4,직군코드!$A$2:$B$12,2,FALSE) -> 관리 | O4: 003C0100 | P4: 인재양성팀 | Q4: =VLOOKUP(O4,부서코드!$B$9:$C$244,2,FALSE) -> 인재양성팀 | R4: 50 | S4: 1 | T4: 34 | U4: 20181101 | W4: 0 | X4: 1 | Y4: A100 | Z4: 20250101 | AD4: 20210302 | AE4: 20171101 | AH4: 20250101060000 | AI4: SYSTEM | AJ4: 20120627 | AK4: IT201159 | AL4: 0000 | AM4: 19990524 | AO4: 03
A5: IT200247 | B5: 이명계 | C5: 650725 | D5: 450401ABD7C5BBCD2D7FD3BD81D65382 | E5: 19990524 | F5: 2 | G5: 2 | H5: 12 | I5: 18 | J5: 19 | K5: 2A | L5: 01 | M5: 관리 | N5: =VLOOKUP(L5,직군코드!$A$2:$B$12,2,FALSE) -> 관리 | O5: 003C0100 | P5: 인재양성팀 | Q5: =VLOOKUP(O5,부서코드!$B$9:$C$244,2,FALSE) -> 인재양성팀 | R5: 50 | S5: 1 | T5: 30 | U5: 20200601 | W5: 0 | X5: 1 | Y5: A100 | Z5: 20250101 | AD5: 20190701 | AE5: 20190601 | AH5: 20250101060000 | AI5: SYSTEM | AJ5: 20120627 | AK5: IT201159 | AL5: 0000 | AM5: 19990524 | AO5: 09
A6: IT200102 | B6: 최동진 | C6: 650813 | D6: 916103E3C2834399C435EFC5328D7076 | E6: 19981218 | F6: 2 | G6: 2 | H6: 12 | I6: 18 | J6: 19 | K6: 1A | L6: 01 | M6: 관리 | N6: =VLOOKUP(L6,직군코드!$A$2:$B$12,2,FALSE) -> 관리 | O6: 003C0100 | P6: 인재양성팀 | Q6: =VLOOKUP(O6,부서코드!$B$9:$C$244,2,FALSE) -> 인재양성팀 | R6: 50 | S6: 1 | T6: 25 | U6: 20150501 | W6: 0 | X6: 1 | Y6: A100 | Z6: 20250101 | AD6: 20190701 | AE6: 20140501 | AH6: 20250101060000 | AI6: SYSTEM | AJ6: 20130102 | AK6: IT201159 | AL6: 0000 | AM6: 19981218 | AO6: 07
A7: IT200194 | B7: 전유준 | C7: 650826 | D7: D7CD007391333E0F65060C54AC99C676 | E7: 19990524 | F7: 2 | G7: 2 | H7: 12 | I7: 18 | J7: 19 | K7: 1A | L7: 01 | M7: 관리 | N7: =VLOOKUP(L7,직군코드!$A$2:$B$12,2,FALSE) -> 관리 | O7: 003C0100 | P7: 인재양성팀 | Q7: =VLOOKUP(O7,부서코드!$B$9:$C$244,2,FALSE) -> 인재양성팀 | R7: 50 | S7: 1 | T7: 29 | U7: 20141101 | W7: 0 | X7: 1 | Y7: A100 | Z7: 20250101 | AD7: 20190325 | AE7: 20131101 | AH7: 20250101060000 | AI7: SYSTEM | AJ7: 20120627 | AK7: IT201159 | AL7: 0000 | AM7: 19990524 | AO7: 03
A8: IT200073 | B8: 유창수 | C8: 650828 | D8: 68A2D27596DF88EC84640EBDE4D48332 | E8: 19981016 | F8: 2 | G8: 2 | H8: 12 | I8: 18 | J8: 19 | K8: 1A | L8: 01 | M8: 관리 | N8: =VLOOKUP(L8,직군코드!$A$2:$B$12,2,FALSE) -> 관리 | O8: 003C0100 | P8: 인재양성팀 | Q8: =VLOOKUP(O8,부서코드!$B$9:$C$244,2,FALSE) -> 인재양성팀 | R8: 50 | S8: 1 | T8: 28 | U8: 20200501 | W8: 0 | X8: 1 | Y8: A100 | Z8: 20250101 | AD8: 20220321 | AE8: 20190501 | AH8: 20250101060000 | AI8: SYSTEM | AL8: 0000 | AM8: 19981016 | AO8: 03
A9: IT200072 | B9: 이세형 | C9: 651114 | D9: FC3EAE36846C21C8A74A39B17D9A1100 | E9: 19981016 | F9: 2 | G9: 2 | H9: 12 | I9: 18 | J9: 19 | K9: 1A | L9: 01 | M9: 관리 | N9: =VLOOKUP(L9,직군코드!$A$2:$B$12,2,FALSE) -> 관리 | O9: 003C0100 | P9: 인재양성팀 | Q9: =VLOOKUP(O9,부서코드!$B$9:$C$244,2,FALSE) -> 인재양성팀 | R9: 50 | S9: 1 | T9: 32 | U9: 20191101 | W9: 0 | X9: 1 | Y9: A100 | Z9: 20250101 | AD9: 20220321 | AE9: 20181101 | AH9: 20250101060000 | AI9: SYSTEM | AJ9: 20120627 | AK9: IT201159 | AL9: 0000 | AM9: 19981016 | AO9: 09
A10: IT200319 | B10: 이경원 | C10: 651117 | D10: 55F625168F8701E168B26EE6F0D91557 | E10: 19990524 | F10: 2 | G10: 2 | H10: 12 | I10: 18 | J10: 19 | K10: 2A | L10: 01 | M10: 관리 | N10: =VLOOKUP(L10,직군코드!$A$2:$B$12,2,FALSE) -> 관리 | O10: 003C0100 | P10: 인재양성팀 | Q10: =VLOOKUP(O10,부서코드!$B$9:$C$244,2,FALSE) -> 인재양성팀 | R10: 50 | S10: 1 | T10: 36 | U10: 20210401 | W10: 0 | X10: 1 | Y10: A100 | Z10: 20250101 | AD10: 20200323 | AE10: 20200401 | AH10: 20250101060000 | AI10: SYSTEM | AL10: 0000 | AM10: 19990524 | AO10: 03
A11: IT201511 | B11: 조영민 | C11: 651120 | D11: 4C5FEF2D304355E750E2A725DF1DCE4B | E11: 20160201 | F11: 4 | G11: 1 | H11: 12 | I11: 18 | J11: 19 | K11: 3A | L11: 01 | M11: 관리 | N11: =VLOOKUP(L11,직군코드!$A$2:$B$12,2,FALSE) -> 관리 | O11: 003C0100 | P11: 인재양성팀 | Q11: =VLOOKUP(O11,부서코드!$B$9:$C$244,2,FALSE) -> 인재양성팀 | R11: 50 | S11: 1 | T11: 38 | U11: 20260701 | W11: 0 | X11: 1 | Y11: A100 | Z11: 20250101 | AD11: 20160201 | AE11: 20250701 | AF11: 20160128 | AG11: IT201349 | AH11: 20250701060000 | AI11: SYSTEM | AL11: 0000 | AM11: 20160201 | AO11: 09
A12: IT200301 | B12: 임준경 | C12: 651124 | D12: A5F8F3E06DD96A26ED10246EEDC3597E | E12: 19990524 | F12: 2 | G12: 1 | H12: 12 | I12: 18 | J12: 19 | K12: 3A | L12: 01 | M12: 관리 | N12: =VLOOKUP(L12,직군코드!$A$2:$B$12,2,FALSE) -> 관리 | O12: 003C0100 | P12: 인재양성팀 | Q12: =VLOOKUP(O12,부서코드!$B$9:$C$244,2,FALSE) -> 인재양성팀 | R12: 50 | S12: 1 | T12: 39 | U12: 20260801 | W12: 0 | X12: 1 | Y12: A100 | Z12: 20250101 | AD12: 20180101 | AE12: 20250801 | AH12: 20250801060000 | AI12: SYSTEM | AL12: 0000 | AM12: 19990524 | AO12: 08
A13: IT200266 | B13: 최승욱 | C13: 651216 | D13: 735538847D2EDC474BF29EB928B1335E | E13: 19990524 | F13: 2 | G13: 2 | H13: 12 | I13: 18 | J13: 19 | K13: 2A | L13: 01 | M13: 관리 | N13: =VLOOKUP(L13,직군코드!$A$2:$B$12,2,FALSE) -> 관리 | O13: 003C0100 | P13: 인재양성팀 | Q13: =VLOOKUP(O13,부서코드!$B$9:$C$244,2,FALSE) -> 인재양성팀 | R13: 50 | S13: 1 | T13: 35 | U13: 20220601 | W13: 0 | X13: 1 | Y13: A100 | Z13: 20250101 | AD13: 20200921 | AE13: 20210601 | AH13: 20250101060000 | AI13: SYSTEM | AJ13: 20130729 | AK13: IT201159 | AL13: 0000 | AM13: 19990524 | AO13: 05
A14: IT200137 | B14: 김성철 | C14: 660113 | D14: B48447388BC7021D9BDA6AA36892AEE2 | E14: 19990302 | F14: 2 | G14: 2 | H14: 12 | I14: 18 | J14: 19 | K14: 1A | L14: 01 | M14: 관리 | N14: =VLOOKUP(L14,직군코드!$A$2:$B$12,2,FALSE) -> 관리 | O14: 003C0100 | P14: 인재양성팀 | Q14: =VLOOKUP(O14,부서코드!$B$9:$C$244,2,FALSE) -> 인재양성팀 | R14: 50 | S14: 1 | T14: 35 | U14: 20200701 | W14: 0 | X14: 1 | Y14: A100 | Z14: 20250701 | AD14: 20230530 | AE14: 20190701 | AH14: 20250701060000 | AI14: SYSTEM | AJ14: 20120627 | AK14: IT201159 | AL14: 0000 | AM14: 19990302 | AO14: 11
A15: IT200275 | B15: 이재남 | C15: 660118 | D15: 4498285206B9E73F7CD5EF0C3E3363DB | E15: 19990524 | F15: 2 | G15: 2 | H15: 12 | I15: 18 | J15: 19 | K15: 3A | L15: 01 | M15: 관리 | N15: =VLOOKUP(L15,직군코드!$A$2:$B$12,2,FALSE) -> 관리 | O15: n | P15: #N/A | Q15: =VLOOKUP(O15,부서코드!$B$9:$C$244,2,FALSE) -> #N/A | R15: 50 | S15: 1 | T15: 34 | U15: 20230701 | W15: 0 | X15: 1 | Y15: A100 | Z15: 20250701 | AD15: 20190701 | AE15: 20220701 | AH15: 20250701060000 | AI15: SYSTEM | AL15: 0000 | AM15: 19990524 | AO15: 03
A16: IT200208 | B16: 장선용 | C16: 660220 | D16: E5D48FB720713E0CD3B5D2B586C2E44B | E16: 19990524 | F16: 2 | G16: 2 | H16: 12 | I16: 18 | J16: 19 | K16: 2A | L16: 01 | M16: 관리 | N16: =VLOOKUP(L16,직군코드!$A$2:$B$12,2,FALSE) -> 관리 | O16: 003C0100 | P16: 인재양성팀 | Q16: =VLOOKUP(O16,부서코드!$B$9:$C$244,2,FALSE) -> 인재양성팀 | R16: 50 | S16: 1 | T16: 32 | U16: 20190501 | W16: 0 | X16: 1 | Y16: A100 | Z16: 20250701 | AD16: 20180101 | AE16: 20180501 | AH16: 20250701060000 | AI16: SYSTEM | AJ16: 20130331 | AK16: IT200834 | AL16: 0000 | AM16: 19990524 | AO16: 10
A17: IT201428 | B17: 고명주 | C17: 660228 | D17: E07B7F520F7954C17A68CAB207E55F08 | E17: 20150330 | F17: 4 | G17: 2 | H17: 12 | I17: 18 | J17: 19 | K17: 3A | L17: 01 | M17: 관리 | N17: =VLOOKUP(L17,직군코드!$A$2:$B$12,2,FALSE) -> 관리 | O17: 003C0100 | P17: 인재양성팀 | Q17: =VLOOKUP(O17,부서코드!$B$9:$C$244,2,FALSE) -> 인재양성팀 | R17: 50 | S17: 1 | T17: 37 | U17: 20250401 | W17: 0 | X17: 1 | Y17: A100 | Z17: 20250701 | AD17: 20150330 | AE17: 20240401 | AF17: 20150327 | AG17: IT200354 | AH17: 20250701060000 | AI17: SYSTEM | AL17: 0000 | AM17: 20150330 | AO17: 03
A18: IT200331 | B18: 김철호 | C18: 660317 | D18: E5D2E5561839EA7B2EB612FED48E53EA | E18: 19990524 | F18: 2 | G18: 2 | H18: 12 | I18: 18 | J18: 19 | K18: 2A | L18: 01 | M18: 관리 | N18: =VLOOKUP(L18,직군코드!$A$2:$B$12,2,FALSE) -> 관리 | O18: 003C0100 | P18: 인재양성팀 | Q18: =VLOOKUP(O18,부서코드!$B$9:$C$244,2,FALSE) -> 인재양성팀 | R18: 50 | S18: 1 | T18: 32 | U18: 20230501 | W18: 0 | X18: 1 | Y18: A100 | Z18: 20250701 | AD18: 20241031 | AE18: 20220501 | AH18: 20250701060000 | AI18: SYSTEM | AL18: 0000 | AM18: 19990524 | AO18: 12
A19: IT200826 | B19: 이주현 | C19: 660415 | D19: 9CD5B306CFD5838B54F2E42010695F2D | E19: 19990910 | F19: 2 | G19: 1 | H19: 12 | I19: 18 | J19: 19 | K19: 3A | L19: 01 | M19: 관리 | N19: =VLOOKUP(L19,직군코드!$A$2:$B$12,2,FALSE) -> 관리 | O19: 003C0100 | P19: 인재양성팀 | Q19: =VLOOKUP(O19,부서코드!$B$9:$C$244,2,FALSE) -> 인재양성팀 | R19: 50 | S19: 1 | T19: 34 | U19: 20260901 | W19: 0 | X19: 1 | Y19: A100 | Z19: 20250701 | AD19: 20210927 | AE19: 20250901 | AH19: 20250901060000 | AI19: SYSTEM | AL19: 0000 | AM19: 19990910 | AO19: 11
A20: IT201230 | B20: 최순양 | C20: 660415 | D20: 3468ED4DA1A7AF70EDD4BF1FDEF9112D | E20: 20110829 | F20: 4 | G20: 1 | H20: 12 | I20: 18 | J20: 19 | K20: 4A | L20: 19 | M20: 차량 | N20: =VLOOKUP(L20,직군코드!$A$2:$B$12,2,FALSE) -> 차량 | O20: 003C0100 | P20: 인재양성팀 | Q20: =VLOOKUP(O20,부서코드!$B$9:$C$244,2,FALSE) -> 인재양성팀 | R20: 50 | S20: 2 | T20: 33 | U20: 20260201 | W20: 0 | X20: 1 | Y20: A100 | Z20: 20250701 | AA20: H20 | AC20: C | AD20: 20210927 | AE20: 20250201 | AF20: 20110826 | AG20: IT201074 | AH20: 20250701060000 | AI20: SYSTEM | AL20: 0000 | AM20: 20110829 | AO20: 11
A21: IT201249 | B21: 이승준 | C21: 660426 | D21: 683248E27A3DE597FA638BD52B41963F | E21: 19971001 | F21: 9 | G21: 2 | H21: 12 | I21: 18 | J21: 19 | K21: 2A | L21: 01 | M21: 관리 | N21: =VLOOKUP(L21,직군코드!$A$2:$B$12,2,FALSE) -> 관리 | O21: 003C0100 | P21: 인재양성팀 | Q21: =VLOOKUP(O21,부서코드!$B$9:$C$244,2,FALSE) -> 인재양성팀 | R21: 50 | S21: 1 | T21: 34 | U21: 20200101 | W21: 0 | X21: 1 | Y21: A100 | Z21: 20250701 | AD21: 20190101 | AE21: 20190101 | AF21: 20111224 | AG21: IT201159 | AH21: 20250701060000 | AI21: SYSTEM | AJ21: 20130102 | AK21: IT201159 | AL21: 0000 | AM21: 19971001 | AO21: 03
A22: IT200113 | B22: 이창호 | C22: 660511 | D22: 3A8A9E3537D38D6FF4065040319A48A9 | E22: 19990222 | F22: 2 | G22: 2 | H22: 12 | I22: 18 | J22: 19 | K22: 3A | L22: 01 | M22: 관리 | N22: =VLOOKUP(L22,직군코드!$A$2:$B$12,2,FALSE) -> 관리 | O22: 003C0100 | P22: 인재양성팀 | Q22: =VLOOKUP(O22,부서코드!$B$9:$C$244,2,FALSE) -> 인재양성팀 | R22: 50 | S22: 1 | T22: 28 | U22: 20230401 | W22: 0 | X22: 1 | Y22: A100 | Z22: 20250701 | AD22: 20180928 | AE22: 20220401 | AH22: 20250701060000 | AI22: SYSTEM | AL22: 0000 | AM22: 19990222 | AO22: 03
A23: IT200313 | B23: 이래문 | C23: 660713 | D23: 3AC527A1A9931F24645399CF8E6BEEBE | E23: 19990524 | F23: 2 | G23: 1 | H23: 12 | I23: 18 | J23: 19 | K23: 3A | L23: 01 | M23: 관리 | N23: =VLOOKUP(L23,직군코드!$A$2:$B$12,2,FALSE) -> 관리 | O23: 002A0201 | P23: 동막신호파트 | Q23: =VLOOKUP(O23,부서코드!$B$9:$C$244,2,FALSE) -> 동막신호파트 | R23: 24 | S23: 1 | T23: 38 | U23: 20260401 | W23: 0 | X23: 0 | Y23: B100 | Z23: 20220321 | AD23: 20220321 | AE23: 20250401 | AH23: 20250401060000 | AI23: SYSTEM | AJ23: 20130102 | AK23: IT201159 | AL23: 0000 | AM23: 19990524 | AO23: 05
A24: IT200038 | B24: 윤동렬 | C24: 660717 | D24: 837A59BE9FF950293D3B72BA77156980 | E24: 19980521 | F24: 1 | G24: 2 | H24: 12 | I24: 18 | J24: 19 | K24: 2A | L24: 01 | M24: 관리 | N24: =VLOOKUP(L24,직군코드!$A$2:$B$12,2,FALSE) -> 관리 | O24: 003C0200 | P24: 기술전수팀 | Q24: =VLOOKUP(O24,부서코드!$B$9:$C$244,2,FALSE) -> 기술전수팀 | R24: 34 | S24: 1 | T24: 28 | U24: 20200501 | W24: 0 | X24: 1 | Y24: A100 | Z24: 20230327 | AD24: 20180701 | AE24: 20190501 | AH24: 20230327060000 | AI24: SYSTEM | AJ24: 20120627 | AK24: IT201159 | AL24: 0000 | AM24: 19980521 | AO24: 11
A25: IT200811 | B25: 김성률 | C25: 660913 | D25: F391359D10BFE5022B0C28268D89B589 | E25: 19990809 | F25: 2 | G25: 2 | H25: 12 | I25: 18 | J25: 19 | K25: 2A | L25: 01 | M25: 관리 | N25: =VLOOKUP(L25,직군코드!$A$2:$B$12,2,FALSE) -> 관리 | O25: 003C0200 | P25: 기술전수팀 | Q25: =VLOOKUP(O25,부서코드!$B$9:$C$244,2,FALSE) -> 기술전수팀 | R25: 34 | S25: 1 | T25: 30 | U25: 20210701 | W25: 0 | X25: 1 | Y25: A100 | Z25: 20250929 | AD25: 20190325 | AE25: 20200701 | AH25: 20250929060000 | AI25: SYSTEM | AJ25: 20120817 | AK25: IT200897 | AL25: 0000 | AM25: 19990809 | AO25: 03
A26: IT200307 | B26: 이영일 | C26: 661105 | D26: A5CE65E95CC9A0871B73D060F7B88A0B | E26: 19990524 | F26: 2 | G26: 1 | H26: 12 | I26: 18 | J26: 19 | K26: 3A | L26: 01 | M26: 관리 | N26: =VLOOKUP(L26,직군코드!$A$2:$B$12,2,FALSE) -> 관리 | O26: 003B0304 | P26: 7호선전자파트 | Q26: =VLOOKUP(O26,부서코드!$B$9:$C$244,2,FALSE) -> 7호선전자파트 | R26: 24 | S26: 1 | T26: 35 | U26: 20260801 | W26: 0 | X26: 0 | Y26: C180 | Z26: 20240329 | AD26: 20200921 | AE26: 20250801 | AH26: 20250801060000 | AI26: SYSTEM | AL26: 0000 | AM26: 19990524 | AO26: 07
A27: IT201430 | B27: 황치성 | C27: 661117 | D27: 7E710CD2C2B25DC4F2BDCE2DD7A65F6F | E27: 20150330 | F27: 4 | G27: 2 | H27: 12 | I27: 18 | J27: 19 | K27: 1A | L27: 01 | M27: 관리 | N27: =VLOOKUP(L27,직군코드!$A$2:$B$12,2,FALSE) -> 관리 | O27: 003C0200 | P27: 기술전수팀 | Q27: =VLOOKUP(O27,부서코드!$B$9:$C$244,2,FALSE) -> 기술전수팀 | R27: 31 | S27: 1 | T27: 32 | U27: 20211001 | W27: 0 | X27: 1 | Y27: A100 | Z27: 20250929 | AD27: 20230925 | AE27: 20201001 | AF27: 20150327 | AG27: IT200354 | AH27: 20250929060000 | AI27: SYSTEM | AL27: 0000 | AM27: 20150330 | AO27: 03
A28: IT200164 | B28: 임쌍봉 | C28: 661202 | D28: 1AAAEDB10E5DD4E9FF5E6AEADA5CE0B1 | E28: 19990302 | F28: 2 | G28: 2 | H28: 12 | I28: 18 | J28: 19 | K28: 1A | L28: 01 | M28: 관리 | N28: =VLOOKUP(L28,직군코드!$A$2:$B$12,2,FALSE) -> 관리 | O28: 003C0200 | P28: 기술전수팀 | Q28: =VLOOKUP(O28,부서코드!$B$9:$C$244,2,FALSE) -> 기술전수팀 | R28: 31 | S28: 1 | T28: 34 | U28: 20210301 | W28: 0 | X28: 1 | Y28: A100 | Z28: 20250929 | AD28: 20250310 | AE28: 20200301 | AH28: 20250929060000 | AI28: SYSTEM | AL28: 0000 | AM28: 19990302 | AO28: 07
A29: IT200091 | B29: 백봉현 | C29: 670106 | D29: 53A2A4451BFDB67B07CC81EEFC0F197A | E29: 19981112 | F29: 2 | G29: 2 | H29: 12 | I29: 18 | J29: 19 | K29: 2A | L29: 01 | M29: 관리 | N29: =VLOOKUP(L29,직군코드!$A$2:$B$12,2,FALSE) -> 관리 | O29: 003C0200 | P29: 기술전수팀 | Q29: =VLOOKUP(O29,부서코드!$B$9:$C$244,2,FALSE) -> 기술전수팀 | R29: 34 | S29: 1 | T29: 33 | U29: 20201001 | W29: 0 | X29: 1 | Y29: A100 | Z29: 20250724 | AD29: 20180701 | AE29: 20191001 | AH29: 20250724060000 | AI29: SYSTEM | AJ29: 20120627 | AK29: IT201159 | AL29: 0000 | AM29: 19981112 | AO29: 08
A30: IT200816 | B30: 배성원 | C30: 670117 | D30: 3A0F0929328AAF8101F11D582209DF0A | E30: 19990809 | F30: 2 | G30: 2 | H30: 12 | I30: 18 | J30: 19 | K30: 2A | L30: 01 | M30: 관리 | N30: =VLOOKUP(L30,직군코드!$A$2:$B$12,2,FALSE) -> 관리 | O30: 003C0200 | P30: 기술전수팀 | Q30: =VLOOKUP(O30,부서코드!$B$9:$C$244,2,FALSE) -> 기술전수팀 | R30: 34 | S30: 1 | T30: 32 | U30: 20210301 | W30: 0 | X30: 1 | Y30: A100 | Z30: 20250724 | AD30: 20190325 | AE30: 20200301 | AH30: 20250724060000 | AI30: SYSTEM | AJ30: 20120627 | AK30: IT201159 | AL30: 0000 | AM30: 19990809 | AO30: 09
A31: IT200318 | B31: 이광조 | C31: 670301 | D31: 062107A97933392543FDC1F88EB57C74 | E31: 19990524 | F31: 2 | G31: 1 | H31: 12 | I31: 18 | J31: 19 | K31: 3A | L31: 01 | M31: 관리 | N31: =VLOOKUP(L31,직군코드!$A$2:$B$12,2,FALSE) -> 관리 | O31: 002A0301 | P31: 지식정보단지통신파트 | Q31: =VLOOKUP(O31,부서코드!$B$9:$C$244,2,FALSE) -> 지식정보단지통신파트 | R31: 24 | S31: 1 | T31: 37 | U31: 20260801 | W31: 0 | X31: 0 | Y31: B100 | Z31: 20240329 | AD31: 20200921 | AE31: 20250801 | AH31: 20250801060000 | AI31: SYSTEM | AL31: 0000 | AM31: 19990524 | AO31: 06
A32: IT200321 | B32: 한인숙 | C32: 670315 | D32: 43B99E5A46EF0ACBA1DAA386A61D2538 | E32: 19990524 | F32: 2 | G32: 2 | H32: 12 | I32: 18 | J32: 19 | K32: 3A | L32: 01 | M32: 관리 | N32: =VLOOKUP(L32,직군코드!$A$2:$B$12,2,FALSE) -> 관리 | O32: 000W0100 | P32: 교통연수팀 | Q32: =VLOOKUP(O32,부서코드!$B$9:$C$244,2,FALSE) -> 교통연수팀 | R32: 21 | S32: 1 | T32: 33 | U32: 20220501 | W32: 0 | X32: 0 | Y32: C1B0 | Z32: 20241022 | AD32: 20180701 | AE32: 20210501 | AH32: 20250404060000 | AI32: SYSTEM | AL32: 0000 | AM32: 19990524 | AO32: 03
A33: IT200061 | B33: 유창하 | C33: 670329 | D33: 20FDED601B34A14D2EF3AA0C645FA69E | E33: 19981007 | F33: 2 | G33: 2 | H33: 12 | I33: 18 | J33: 19 | K33: 2A | L33: 01 | M33: 관리 | N33: =VLOOKUP(L33,직군코드!$A$2:$B$12,2,FALSE) -> 관리 | O33: 003C0200 | P33: 기술전수팀 | Q33: =VLOOKUP(O33,부서코드!$B$9:$C$244,2,FALSE) -> 기술전수팀 | R33: 34 | S33: 1 | T33: 36 | U33: 20241201 | W33: 0 | X33: 1 | Y33: A100 | Z33: 20250404 | AD33: 20240329 | AE33: 20231201 | AH33: 20250404060000 | AI33: SYSTEM | AL33: 0000 | AM33: 19981007 | AO33: 07
A34: IT200339 | B34: 현광진 | C34: 670401 | D34: 42E99D43F45FDB3076F118F7AF5A4A85 | E34: 19990524 | F34: 2 | G34: 1 | H34: 12 | I34: 18 | J34: 19 | K34: 3A | L34: 01 | M34: 관리 | N34: =VLOOKUP(L34,직군코드!$A$2:$B$12,2,FALSE) -> 관리 | O34: 000K0300 | P34: 귤현중정비팀 | Q34: =VLOOKUP(O34,부서코드!$B$9:$C$244,2,FALSE) -> 귤현중정비팀 | R34: 21 | S34: 1 | T34: 34 | U34: 20260901 | W34: 0 | X34: 0 | Y34: B100 | Z34: 20240101 | AD34: 20200330 | AE34: 20250901 | AH34: 20250901060000 | AI34: SYSTEM | AL34: 0000 | AM34: 19990524 | AO34: 11
A35: IT201254 | B35: 김영순 | C35: 670730 | D35: C7874BED8776CFFD27838480BDDE764B | E35: 20061201 | F35: 9 | G35: 1 | H35: 12 | I35: 18 | J35: 19 | K35: 2A | L35: 01 | M35: 관리 | N35: =VLOOKUP(L35,직군코드!$A$2:$B$12,2,FALSE) -> 관리 | O35: 000N0470 | P35: 검단오류관리역 | Q35: =VLOOKUP(O35,부서코드!$B$9:$C$244,2,FALSE) -> 검단오류관리역 | R35: 22 | S35: 1 | T35: 37 | U35: 20260101 | W35: 0 | X35: 0 | Y35: B1V0 | Z35: 20241022 | AD35: 20250310 | AE35: 20250101 | AF35: 20111224 | AG35: IT201159 | AH35: 20250310060000 | AI35: SYSTEM | AJ35: 20120516 | AK35: IT201159 | AL35: 0000 | AM35: 20061201 | AO35: 03
A36: IT200251 | B36: 하태신 | C36: 670810 | D36: 10396E8ED9DEF236E47380F51BA2794B | E36: 19990524 | F36: 2 | G36: 1 | H36: 12 | I36: 18 | J36: 19 | K36: 3A | L36: 01 | M36: 관리 | N36: =VLOOKUP(L36,직군코드!$A$2:$B$12,2,FALSE) -> 관리 | O36: 002B0101 | P36: 작전토목파트 | Q36: =VLOOKUP(O36,부서코드!$B$9:$C$244,2,FALSE) -> 작전토목파트 | R36: 24 | S36: 1 | T36: 35 | U36: 20251201 | W36: 0 | X36: 0 | Y36: B100 | Z36: 20250311 | AD36: 20160229 | AE36: 20241201 | AH36: 20250311060000 | AI36: SYSTEM | AL36: 0000 | AM36: 19990524 | AO36: 08
A37: IT201241 | B37: 최종국 | C37: 670817 | D37: E49F4DC3F0612EF003BA35BC12391181 | E37: 19971001 | F37: 9 | G37: 2 | H37: 12 | I37: 18 | J37: 19 | K37: 2A | L37: 01 | M37: 관리 | N37: =VLOOKUP(L37,직군코드!$A$2:$B$12,2,FALSE) -> 관리 | O37: 000N0410 | P37: 인천대공원관리역 | Q37: =VLOOKUP(O37,부서코드!$B$9:$C$244,2,FALSE) -> 인천대공원관리역 | R37: 22 | S37: 1 | T37: 35 | U37: 20210101 | W37: 0 | X37: 0 | Y37: B1V0 | Z37: 20241022 | AD37: 20190701 | AE37: 20200101 | AF37: 20111224 | AG37: IT201159 | AH37: 20241022060000 | AI37: SYSTEM | AJ37: 20120725 | AK37: IT200860 | AL37: 0000 | AM37: 19971001 | AO37: 03
A38: IT200104 | B38: 이제철 | C38: 670819 | D38: C89F8BC7CEE8FF2587F71B21A694B659 | E38: 19981218 | F38: 2 | G38: 2 | H38: 12 | I38: 18 | J38: 19 | K38: 1A | L38: 01 | M38: 관리 | N38: =VLOOKUP(L38,직군코드!$A$2:$B$12,2,FALSE) -> 관리 | O38: 000H0100 | P38: 철도안전팀 | Q38: =VLOOKUP(O38,부서코드!$B$9:$C$244,2,FALSE) -> 철도안전팀 | R38: 1B | S38: 1 | T38: 29 | U38: 20180701 | W38: 0 | X38: 0 | Y38: B200 | Z38: 20230227 | AD38: 20200323 | AE38: 20170701 | AH38: 20230327060000 | AI38: SYSTEM | AJ38: 20120627 | AK38: IT201159 | AL38: 0000 | AM38: 19981218 | AO38: 05
A39: IT200053 | B39: 현웅대 | C39: 670923 | D39: 8B73E595BC1F1E1984D1E054D715D5DB | E39: 19981007 | F39: 2 | G39: 2 | H39: 12 | I39: 18 | J39: 19 | K39: 1A | L39: 01 | M39: 관리 | N39: =VLOOKUP(L39,직군코드!$A$2:$B$12,2,FALSE) -> 관리 | O39: 000W0100 | P39: 교통연수팀 | Q39: =VLOOKUP(O39,부서코드!$B$9:$C$244,2,FALSE) -> 교통연수팀 | R39: 1G | S39: 1 | T39: 26 | U39: 20150501 | W39: 0 | X39: 0 | Y39: C1B0 | Z39: 20250929 | AD39: 20200921 | AE39: 20140501 | AH39: 20250929060000 | AI39: SYSTEM | AJ39: 20120627 | AK39: IT201159 | AL39: 0000 | AM39: 19981007 | AO39: 03
A40: IT200303 | B40: 김완기 | C40: 671027 | D40: 862543C29B660BAA7DA5E47240362F9D | E40: 19990524 | F40: 2 | G40: 1 | H40: 12 | I40: 18 | J40: 19 | K40: 3A | L40: 01 | M40: 관리 | N40: =VLOOKUP(L40,직군코드!$A$2:$B$12,2,FALSE) -> 관리 | O40: 002B0108 | P40: 동막토목파트 | Q40: =VLOOKUP(O40,부서코드!$B$9:$C$244,2,FALSE) -> 동막토목파트 | R40: 24 | S40: 1 | T40: 38 | U40: 20260701 | W40: 0 | X40: 0 | Y40: B100 | Z40: 20250311 | AD40: 20180101 | AE40: 20250701 | AH40: 20250701060000 | AI40: SYSTEM | AL40: 0000 | AM40: 19990524 | AO40: 08
...

Sheet 직군코드
A1: JOBGRPH | B1: JOBPHNM
A2: 00 | B2: 임원
A3: 91 | B3: 청경
A4: 12 | B4: 일반
A5: 13 | B5: 기능
A6: 14 | B6: 공무
A7: 21 | B7: 시설환경
A8: 01 | B8: 관리
A9: 22 | B9: 전기전자
A10: 20 | B10: 승무
A11: 19 | B11: 차량
A12: 03 | B12: 사무

Sheet 부서코드
B2: pm110a | D2: 부서코드현황
G5: 2025.11.14 13:25
G6: IT201368
A7: 출력순서 | B7: 부서코드 | C7: 부서명(약칭) | D7: 부서명 | E7: 사업장 | F7: 원가 | G7: 사용유무 | H7: 조합가입
A8: AAAAA | B8: 0 | C8: 인천교통공사 | D8: 인천교통공사 | E8: 본사 | G8: 사용 | H8: 미가입
A9: A0000 | B9: 000A0000 | C9: 임원 | D9: 임원 | E9: 본사 | G9: 사용 | H9: 미가입
A10: A0100 | B10: 000A0100 | C10: 임원 | D10: 임원 | E10: 본사 | F10: 판관비 | G10: 사용 | H10: 미가입
A11: B0000 | B11: 000B0000 | C11: 기획조정처 | D11: 기획조정처 | E11: 본사 | G11: 사용 | H11: 미가입
A12: B0100 | B12: 000B0100 | C12: ESG기획팀 | D12: 기획조정처 ESG기획팀 | E12: 본사 | G12: 사용 | H12: 가입
A13: B0200 | B13: 000B1100 | C13: 혁신평가팀 | D13: 기획조정처 혁신평가팀 | E13: 본사 | F13: 판관비 | G13: 사용 | H13: 가입
A14: B0250 | B14: 000B0200 | C14: 예산관리팀 | D14: 기획조정처 예산관리팀 | E14: 본사 | G14: 사용 | H14: 가입
A15: B0300 | B15: 000B0400 | C15: 미디어팀 | D15: 기획조정처 미디어팀 | E15: 본사 | F15: 판관비 | G15: 사용 | H15: 가입
A16: C0000 | B16: 000C0000 | C16: 경영지원처 | D16: 경영지원처 | E16: 본사 | G16: 사용 | H16: 미가입
A17: C0100 | B17: 000C0100 | C17: 총무인사팀 | D17: 경영지원처 총무인사팀 | E17: 본사 | F17: 판관비 | G17: 사용 | H17: 미가입
A18: C0300 | B18: 000C0300 | C18: 노사협력팀 | D18: 경영지원처 노사협력팀 | E18: 본사 | F18: 판관비 | G18: 사용 | H18: 미가입
A19: C0400 | B19: 000C0400 | C19: 재무회계팀 | D19: 경영지원처 재무회계팀 | E19: 본사 | F19: 판관비 | G19: 사용 | H19: 가입
A20: C0500 | B20: 000C0900 | C20: 스마트정보팀 | D20: 경영지원처 스마트정보팀 | E20: 본사 | F20: 판관비 | G20: 사용 | H20: 가입
A21: D0000 | B21: 000D0000 | C21: 도시철도영업처 | D21: 도시철도영업처 | E21: 본사 | G21: 사용 | H21: 미가입
A22: D0100 | B22: 000D0100 | C22: 운수기획팀 | D22: 도시철도영업처 운수기획팀 | E22: 본사 | F22: 판관비 | G22: 사용 | H22: 가입
A23: D0200 | B23: 000D1200 | C23: 고객지원팀 | D23: 도시철도영업처 고객지원팀 | E23: 본사 | G23: 사용 | H23: 가입
A24: D0300 | B24: 000D1400 | C24: 신사업개발팀 | D24: 도시철도영업처 신사업개발팀 | E24: 본사 | F24: 판관비 | G24: 사용 | H24: 가입
A25: D0400 | B25: 000D1500 | C25: 부대사업팀 | D25: 도시철도영업처 부대사업팀 | E25: 본사 | F25: 판관비 | G25: 사용 | H25: 가입
A26: D0500 | B26: 000D1600 | C26: 연구개발팀 | D26: 도시철도영업처 연구개발팀 | E26: 본사 | F26: 판관비 | G26: 사용 | H26: 가입
A27: D0800 | B27: 0 | C27: 차량승무처 | D27: 차량승무처 | E27: 본사 | F27: 매출 | G27: 사용 | H27: 가입
A28: D0820 | B28: 0 | C28: 차량팀 | D28: 차량승무처 차량팀 | E28: 본사 | F28: 매출 | G28: 사용 | H28: 가입
A29: D0830 | B29: 0 | C29: 승무팀 | D29: 차량승무처 승무팀 | E29: 본사 | G29: 사용 | H29: 가입
A30: D0900 | B30: 000E0400 | C30: 월미기술팀 | D30: 차량승무처 월미기술팀 | E30: 본사 | G30: 사용 | H30: 가입
A31: D0910 | B31: 000E0401 | C31: 월미관제파트 | D31: 차량승무처 월미기술팀 관제파트 | E31: 본사 | G31: 사용 | H31: 가입
A32: E0000 | B32: 000G0000 | C32: 시스템관리처 | D32: 시스템관리처 | E32: 본사 | G32: 사용 | H32: 미가입
A33: E0200 | B33: 000G1000 | C33: 전기팀 | D33: 시스템관리처 전기팀 | E33: 본사 | F33: 매출 | G33: 사용 | H33: 가입
A34: E0300 | B34: 000G1100 | C34: 신호팀 | D34: 시스템관리처 신호팀 | E34: 본사 | F34: 매출 | G34: 사용 | H34: 가입
A35: E0400 | B35: 000G0400 | C35: 통신팀 | D35: 시스템관리처 통신팀 | E35: 본사 | G35: 사용 | H35: 가입
A36: E0411 | B36: 000G1800 | C36: 전기설비개량TF팀 | D36: 시스템관리처 전기설비개량TF팀 | E36: 본사 | F36: 매출 | G36: 사용 | H36: 가입
A37: E0500 | B37: 000F0000 | C37: 시설환경처 | D37: 시설환경처 | E37: 본사 | G37: 사용 | H37: 미가입
A38: E0600 | B38: 000F0100 | C38: 토목궤도팀 | D38: 시설환경처 토목궤도팀 | E38: 본사 | G38: 사용 | H38: 가입
A39: E0650 | B39: 000F0700 | C39: 건축팀 | D39: 시설환경처 건축팀 | E39: 본사 | G39: 사용 | H39: 가입
A40: E0700 | B40: 000F0200 | C40: 기계환경팀 | D40: 시설환경처 기계환경팀 | E40: 본사 | G40: 사용 | H40: 가입
A41: E0900 | B41: 000F0900 | C41: 공기질개선TF팀 | D41: 시설환경처 공기질개선TF팀 | E41: 본사 | G41: 사용 | H41: 가입
A42: E1000 | B42: 000F1000 | C42: 전자팀 | D42: 시설환경처 전자팀 | E42: 본사 | G42: 사용 | H42: 가입
A43: E1001 | B43: 000F1100 | C43: 건설공사TF팀 | D43: 시설환경처 건설공사TF팀 | E43: 본사 | G43: 사용 | H43: 가입
...
